Traceback (most recent call last):
  File "<string>", line 2, in <module>
  File "library/python/runtime/importer.pxi", line 266, in __res.ResourceImporter.run_main
    self.load_module(entry_point, fix_name='__main__')
  File "library/python/runtime/importer.pxi", line 237, in __res.ResourceImporter.load_module
    exec code in mod.__dict__
  File "library/python/runtime/test/traceback/__main__.py", line 8, in <module>
    main()
  File "library/python/runtime/test/traceback/crash.py", line 48, in main
    one()
  File "library/python/runtime/test/traceback/crash.py", line 16, in one
    modfunc(two)  # aaa
  File "library/python/runtime/test/traceback/mod/__init__.py", line 8, in modfunc
    f()  # call back to caller
  File "library/python/runtime/test/traceback/crash.py", line 20, in two
    three(42)
  File "library/python/runtime/test/traceback/crash.py", line 24, in three
    raise RuntimeError('Kaboom! I\'m dead: {}'.format(x))
RuntimeError: Kaboom! I'm dead: 42
